Workbook

Sheet README
B2: Arsitektur World Model pada Domain Video: Perbandingan Joint Embedding Predictive Architectures (JEPA) dan Generatif
B4: Anggota
B5: M. Hikari Reiziq Rakhmadinta | C5: 5027241079
B6: Arya Bisma Putra Refman | C6: 5027241036
B7: Ahmad Syauqi Reza | C7: 50027241085
B8: M. Fatihul Qolbi Ash Shidiqi | C8: 5027241023
B10: Kitchenham-Style Systematic Literature Review Workbook
B11: Workflow: Raw Article Data → Inclusion/Exclusion Screening → Candidate Papers → Quality Assessment → Final Papers
B12: Purpose | C12: A practical Excel template for conducting a systematic literature review using the main stages described by Kitchenham & Charters: identification, study selection, quality assessment, data extraction, and synthesis.
B13: Important note | C13: Kitchenham does not prescribe one universal numerical inclusion/exclusion score or one universal quality checklist. The scoring rules in this workbook are an operational template that should be adapted to your review protocol and research questions.
B14: PICOC & Search Strategy | C14: Use PICOC_RQs to define Population, Intervention, Comparison, Outcome, and Context and formulate RQs. Use Search_Strategy to document exact database queries, dates, filters, fields, and results. Use Databases to document database selection.
B15: Raw_Articles | C15: Enter every record retrieved from databases/registers and, when applicable, other identification methods such as backward/forward snowballing.
B16: Screening | C16: Apply your predefined inclusion and exclusion criteria. The workbook calculates an inclusion score and identifies candidate papers.
B17: Quality_Assessment | C17: Assess candidate papers using a tailored quality checklist. Default scoring: Yes = 1, Partly = 0.5, No/Unknown = 0.
B18: Final_Papers | C18: Contains papers that pass the quality threshold and are retained for final data extraction.
B19: PRISMA_Counts | C19: Summarizes counts needed to help populate a PRISMA 2020 flow diagram.
B20: Recommended practice | C20: Define inclusion/exclusion criteria and QA thresholds in your protocol before screening. Pilot the criteria on a small sample and revise them if they cannot be applied consistently.
B21: QA scoring | C21: QA uses a 1–3 scale: 1 = Low quality, 2 = Moderate quality, 3 = High quality. With 8 QA questions, maximum score = 24.
B22: QA decision | C22: Default threshold: ≥75% = Final; 60–74.9% = Review; <60% = Exclude. These thresholds are configurable and should be justified in the review protocol.

Sheet PICOC_RQs
B2: PICOC Framework & Research Question Formulation
B3: Use PICOC to translate the research problem into searchable concepts and formulate focused research questions.
B5: Element | C5: Meaning | D5: Your Definition | E5: Notes
B6: P – Population | C6: Who/what is being studied? | D6: Sistem kecerdasan buatan dengan world model untuk simulasi dan prediksi kelanjutan adegan pada lingkungan digital | E6: Model yang memetakan kondisi saat ini ke kondisi masa depan
B7: I – Intervention | C7: Technology, method, treatment, or approach being investigated | D7: Arsitektur berbasis representasi laten non-generatif (JEPA) | E7: I-JEPA, V-JEPA, MC-JEPA, LeWM
B8: C – Comparison | C8: Alternative intervention, baseline, or comparator | D8: Arsitektur world model generatif berbasis piksel/video/diffusion | E8: Video diffusion models, autoregressive, DreamerV3, Ha & Schmidhuber
B9: O – Outcome | C9: What result/effect/performance is being evaluated? | D9: Efisiensi komputasi (FLOPs/memori), efisiensi data/sampel, stabilitas representasi (minim kolaps/halusinasi), dan performa pada tugas hilir (downstream tasks) — dibatasi ke tiga kelompok: (1) video/frame prediction (FVD/PSNR/SSIM), (2) representation probing dengan frozen encoder (action recognition, image/video classification), dan (3) planning/control pada simulasi digital (model-based RL). | E9: Metrik komputasi, akurasi probing, konsistensi representasi
B10: C – Context | C10: Environment/domain in which the study occurs | D10: Pemodelan visual, representasi data video, dan lingkungan simulasi digital | E10: Benchmark video (action-conditioned), gim simulasi murni perangkat lunak
B13: Research Question Formulation
B15: RQ ID | C15: Research Question | D15: PICOC Elements Used
B16: RQ-01 | C16: Apa saja paradigma arsitektural utama pada garis keturunan JEPA dan garis keturunan generatif dalam pemodelan dunia (world modeling), dan bagaimana evolusinya sejak 2018 hingga saat ini? | D16: P, I, C(Comparison)
B17: RQ-02 | C17: Apa perbedaan mendasar dalam fungsi objektif pembelajaran (loss functions) dan strategi representasi antara world model berbasis JEPA (prediksi laten) dan generatif (prediksi piksel)? | D17: I, C(Comparison), O
B18: RQ-03 | C18: Bagaimana perbandingan performa masing-masing garis keturunan pada tugas prediksi sekuens video (video prediction) dan simulasi interaktif pada lingkungan virtual? | D18: I, C(Comparison), O, C(Context)
B19: RQ-04 | C19: Bagaimana trade-off efisiensi komputasi dan efisiensi sampel antara world model berbasis JEPA dan world model generatif? | D19: I, C(Comparison), O
B20: RQ-05 | C20: Apa dataset benchmark dan metrik evaluasi yang umum digunakan komunitas riset untuk mengukur kualitas world model pada kedua pendekatan tersebut? | D20: O, C(Context)
B21: RQ-06 | C21: Apa tantangan terbuka dan arah penelitian masa depan dalam menggabungkan atau memilih antara kedua garis keturunan tersebut dalam pengembangan world model? | D21: I, C(Comparison), C(Context)

Sheet Search_Strategy
B2: Detailed Search Strategy
B3: Document the complete, reproducible search process. Keep the exact query used for every database.
B5: Protocol Item | C5: Value | D5: Guidance
B6: Search Objective | C6: Mengidentifikasi studi yang mengusulkan, mengevaluasi, atau membandingkan arsitektur world model berbasis JEPA dan generatif pada domain video dan simulasi digital, dengan fokus pada tiga tugas hilir (downstream tasks): video/frame prediction, representation probing untuk pemahaman visual/aksi, dan planning/control pada simulasi digital (model-based RL). | D6: State what the search is designed to identify.
B7: Search Period | C7: Januari 2018 - September 2026 | D7: Example: January 2018 – December 2026
B8: Search Date(s) | C8: Akan dicatat saat pelaksanaan pencarian (tahap Conducting), direncanakan pada minggu pertama setelah protokol ini disetujui | D8: Record actual search dates.
B9: Search Queries | C9: ("world model" OR "world models" OR "learned dynamics model" OR "latent dynamics model") AND ("JEPA" OR "joint embedding predictive architecture" OR "I-JEPA" OR "V-JEPA" OR "generative world model" OR "diffusion world model" OR "autoregressive world model") AND ("video prediction" OR "frame prediction" OR "action recognition" OR "probing" OR "planning" OR "model-based RL" OR "model-based reinforcement learning" OR "interactive simulation" OR "virtual environment") | D9: Example: ("intrution detection" OR "intrution detection system" OR "IDS") AND ("machine learning" OR "deep learning")
B10: Publication Type | C10: Hanya artikel jurnal ilmiah (peer-reviewed journal articles). Prosiding konferensi, naskah preprint (arXiv), buku, bab buku, editorial, dan laporan teknis ditolak. | D10: Journal articles, conference papers, etc.
B11: Snowballing | C11: Both (backward dan forward snowballing) dari artikel rujukan kunci (mis. Ha & Schmidhuber, 2018; LeCun, 2022; Assran et al., 2023; Bardes et al., 2024) khusus untuk melacak artikel jurnal ilmiah yang mensitasi atau disitasi oleh karya perintis tersebut. | D11: Backward / forward / both / none
B12: Other Search Methods | C12: Pencarian komplementer melalui Google Scholar untuk melacak artikel jurnal yang belum terindeks di basis data utama; penelusuran manual (hand-searching) pada arsip jurnal terbitan IEEE, ACM, dan ScienceDirect. | D12: Hand-searching, grey literature, websites, etc.
B15: Database Search Log (diisi saat proses conducting)
B17: Database/Source | C17: Platform/URL | D17: Search Date | E17: Exact Search String | F17: Filters / Limits | G17: Results Returned (number of papers) | H17: Notes
B18: Scopus | C18: https://www.scopus.com | D18: 46282 | E18: TITLE-ABS-KEY ( ( "world model" OR "world models" OR "learned dynamics model" OR "latent dynamics model" ) AND ( "JEPA" OR "joint embedding predictive architecture" OR "I-JEPA" OR "V-JEPA" OR "generative world model" OR "diffusion world model" OR "autoregressive world model" ) AND ( "video prediction" OR "frame prediction" OR "action recognition" OR "probing" OR "planning" OR "model-based RL" OR "model-based reinforcement learning" OR "interactive simulation" OR "virtual environment" ) ) AND PUBYEAR > 2017 AND PUBYEAR < 2027 AND DOCTYPE ( ar ) AND LANGUAGE ( english ) | F18: Terintegrasi dalam query string (Years: 2018–2026; Language: English; Document Type: Article) | G18: 6 | H18: Pencarian studi primer jurnal ilmiah peer-reviewed; difokuskan pada tiga downstream tasks sesuai protokol. Ditemukan 6 artikel jurnal yang relevan.
B19: IEEE Xplore | C19: https://ieeexplore.ieee.org | D19: 46282 | E19: ("All Metadata":"world model" OR "All Metadata":"world models" OR "All Metadata":"learned dynamics model" OR "All Metadata":"latent dynamics model") AND ("All Metadata":"JEPA" OR "All Metadata":"joint embedding predictive architecture" OR "All Metadata":"I-JEPA" OR "All Metadata":"V-JEPA" OR "All Metadata":"generative world model" OR "All Metadata":"diffusion world model" OR "All Metadata":"autoregressive world model") AND ("All Metadata":"video prediction" OR "All Metadata":"frame prediction" OR "All Metadata":"action recognition" OR "All Metadata":"probing" OR "All Metadata":"planning" OR "All Metadata":"model-based RL" OR "All Metadata":"model-based reinforcement learning" OR "All Metadata":"interactive simulation" OR "All Metadata":"virtual environment") | F19: Publication Years: 2018–2026 (rentang riil dokumen terjaring: 2022–2026); Content Type: Journals; Field: All Metadata | G19: 2 | H19: Pencarian Command Search pada IEEE Xplore. Seluruh dokumen yang teridentifikasi terbit antara tahun 2022–2026 sehingga otomatis memenuhi batasan periode protokol. Dibatasi ketat pada artikel jurnal ilmiah (menyaring 2 artikel jurnal dan mengeksklusikan 6 prosiding konferensi).
B20: ScienceDirect | C20: ScienceDirect.com | D20: 46283 | E20: ("world model" OR "world models") AND ("JEPA" OR "generative" OR "diffusion") AND ("video prediction" OR "planning" OR "probing") | F20: Field: Title, abstract, author-specified keywords; Years: 2018–2026; Article types: Research articles | G20: 2 | H20: Kueri 3 kluster (Populasi, Mazhab, dan 3 Downstream Tasks) dengan pembatasan 7 operator Boolean bawaan ScienceDirect. Filter dibatasi murni pada Research articles terbitan Elsevier (jurnal Expert Systems with Applications dan Engineering Applications of Artificial Intelligence); buku, bab buku, dan ensiklopedia dieksklusikan.
B21: Google Scholar | C21: https://scholar.google.com/ | D21: 46274 | E21: ("world model" OR "world models" OR "latent dynamics model") AND ("JEPA" OR "joint embedding predictive architecture" OR "I-JEPA" OR "V-JEPA" OR "generative world model" OR "diffusion world model") AND ("video prediction" OR "video generation" OR "interactive simulation") | F21: Rentang tahun (Custom range): 2018-2026; opsi "sertakan paten" tidak dicentang; "mencakup kutipan" dicentang (default Google Scholar) | G21: 1630 | H21: Angka "Sekitar 1.630 hasil" adalah ESTIMASI dari Google Scholar, bukan hitungan presisi seperti Scopus/IEEE (nilai ini diketahui bisa berubah antar-load/halaman). Cakupan Scholar jauh lebih luas dan tidak terkurasi dibanding Scopus/IEEE -- ikut menghitung preprint, tesis, dan laporan non-peer-review -- sehingga 1.630 tidak sebanding langsung dengan 132 (Scopus) atau 5 (IEEE). Sesuai protokol (lihat Other Search Methods), Google Scholar diposisikan sebagai pelengkap/snowballing, bukan sumber utama untuk PRISMA count.
B22: ACM Digital Library | C22: https://dl.acm.org | D22: 46276 | E22: [[All: "world model"] OR [All: "world models"] OR [All: "learned dynamics model"] OR [All: "latent dynamics model"]] AND [[All: "jepa"] OR [All: "joint embedding predictive architecture"] OR [All: "i-jepa"] OR [All: "v-jepa"] OR [All: "generative world model"] OR [All: "diffusion world model"] OR [All: "video generation"] OR [All: "autoregressive video"]] | F22: None (fitur rentang tanggal dibatasi akun premium; batasan tahun 2018–2026 disaring manual saat screening) | G22: 134 | H22: Pencarian pada The ACM Full-Text Collection (861.309 record); 134 dokumen teridentifikasi dan siap diekspor untuk deduplikasi.
B49: Search String Construction
B51: Concept | C51: PICOC Link | D51: Primary Terms | E51: Synonyms / Variants | F51: Final Block
B52: World Model (Dasar) | C52: P | D52: world model | E52: world models; learned dynamics model; latent dynamics model; world modeling | F52: ("world model" OR "world models" OR "learned dynamics model" OR "latent dynamics model")
B53: JEPA Lineage | C53: I | D53: JEPA | E53: joint embedding predictive architecture; I-JEPA; V-JEPA; MC-JEPA | F53: ("JEPA" OR "joint embedding predictive architecture" OR "I-JEPA" OR "V-JEPA")
B54: Generative Lineage | C54: C (Comparison) | D54: generative world model | E54: diffusion world model; autoregressive world model; video diffusion model | F54: ("generative world model" OR "diffusion world model" OR "autoregressive world model")
B55: Downstream Tasks (Outcome) | C55: O | D55: downstream tasks | E55: video prediction; frame prediction; action recognition; representation probing; planning; model-based RL; model-based reinforcement learning | F55: ("video prediction" OR "frame prediction" OR "action recognition" OR "probing" OR "planning" OR "model-based RL" OR "model-based reinforcement learning")
B56: Context (Domain & Simulation) | C56: C (Context) | D56: virtual environment | E56: interactive simulation; digital simulation; visual sequence | F56: ("interactive simulation" OR "virtual environment" OR "visual sequence")
B59: Recommended Search Logic
B61: Within a concept: OR | C61: (term1 OR synonym1 OR synonym2)
B62: Between major concepts: AND | C62: (Population terms) AND (Intervention terms) AND (Outcome terms) | D62: Detailed Search Strategy
B63: Optional concepts | C63: Comparison and Context can be added when they improve precision without unnecessarily excluding relevant studies.

Sheet Protocol_Criteria
B2: Review Protocol & Criteria
B3: Complete this sheet before full screening
B5: Research Question(s) | C5: RQ-01 s/d RQ-06 (lihat sheet PICOC_RQs) - perbandingan arsitektur, objektif pembelajaran, performa prediksi video dan dinamika lingkungan, efisiensi komputasi/sampel, dan tantangan terbuka antara garis keturunan JEPA dan generatif pada world model
B6: Search Databases / Sources | C6: IEEE Xplore, ACM Digital Library, ScienceDirect, Scopus, Google Scholar
B7: Publication Period | C7: Januari 2018 - September 2026
B8: Language | C8: Inggris
B9: Study Type / Design | C9: Hanya artikel jurnal ilmiah peer-reviewed (journal articles) dengan kontribusi arsitektural atau evaluasi empiris yang jelas terhadap world model. Prosiding konferensi, preprint, buku, bab buku, editorial, dan laporan teknis dieksklusi
B10: Inclusion Threshold | C10: Artikel wajib memenuhi IC1, IC2, IC3, dan IC5 (syarat dasar kelayakan). IC4 berfungsi sebagai penguat kualitas/prioritas (bukan syarat wajib), digunakan saat proses Quality Assessment untuk menandai studi dari lab riset utama
B11: Quality Threshold | C11: Default: ≥75% = Final; 60–74.9% = Review; <60% = Exclude. Adapt and justify in your protocol.
B14: Suggested Inclusion Criteria
B16: Code | C16: Criterion
B17: IC1 | C17: Artikel secara langsung mengusulkan, mengevaluasi, atau membandingkan arsitektur world model (berbasis JEPA maupun generatif)
B18: IC2 | C18: Domain aplikasi berkaitan dengan world model pada data video (prediksi video, representasi visual dari observasi berurutan)
B19: IC3 | C19: Diterbitkan dalam rentang Januari 2018 - September 2026
B20: IC4 | C20: Merupakan artikel jurnal atau prosiding konferensi peer-review dari laboratorium riset utama (Meta AI/FAIR, Google DeepMind, NVIDIA Research, dll.)
B21: IC5 | C21: Teks lengkap (full text) tersedia dan berbahasa Inggris
B24: Suggested Exclusion Criteria
B26: Code | C26: Criterion
B27: EC1 | C27: Artikel duplikat yang muncul di lebih dari satu database
B28: EC2 | C28: Diterbitkan di luar rentang periode pencarian (sebelum 2018 atau setelah September 2026)
B29: EC3 | C29: Tidak membahas arsitektur world model atau tidak relevan dengan perbandingan JEPA vs generatif
B30: EC4 | C30: Tidak melibatkan prediksi dinamika lingkungan/dunia (mis. murni pemrosesan bahasa alami tanpa komponen world modeling)
B31: EC5 | C31: Bukan merupakan artikel penuh (hanya abstrak, poster workshop tanpa detail teknis, atau tesis yang belum peer-review)
B32: EC6 | C32: Teks lengkap tidak dapat diakses
B33: EC7 | C33: Merupakan prosiding konferensi, preprint, atau bentuk publikasi non-jurnal lain yang tidak memenuhi kriteria Study Type
B35: Default Quality Assessment Questions
B37: Code | C37: Question
B38: QA1 | C38: Apakah tujuan penelitian/pertanyaan penelitian dinyatakan dengan jelas?
B39: QA2 | C39: Apakah arsitektur world model (JEPA-based atau generative-based) dijelaskan secara jelas, termasuk objektif pembelajaran, input/output, dan representasi laten?
B40: QA3 | C40: Apakah setup eksperimen (dataset, lingkungan simulasi/nyata, baseline pembanding) dijelaskan secara memadai?
B41: QA4 | C41: Apakah metrik evaluasi yang digunakan relevan dengan tugas world modeling (mis. akurasi prediksi, kualitas representasi laten, atau performa pada tugas hilir seperti perencanaan dan prediksi video)?
B42: QA5 | C42: Apakah dilakukan perbandingan terhadap baseline yang relevan, baik dari garis keturunan yang sama maupun garis keturunan lain (JEPA vs generatif)?
B43: QA6 | C43: Apakah hasil penelitian dilaporkan secara jelas dan didukung bukti kuantitatif?
B44: QA7 | C44: Apakah keterbatasan (limitations), kegagalan model, atau ancaman validitas dibahas?
B45: QA8 | C45: Apakah kesimpulan konsisten dengan hasil yang dilaporkan dan memberikan kontribusi baru terhadap diskusi JEPA vs generatif dalam world model?

Sheet Raw_Articles
A1: Article_ID | B1: Source_Type | C1: Database/Source | D1: Search_Date | E1: Search_Query | F1: Title | G1: Authors | H1: Year | I1: Journal/Conference | J1: DOI | K1: URL | L1: Abstract | M1: Document_Type | N1: Language | O1: Duplicate_Key | P1: Duplicate? | Q1: Notes
A2: A0001 | B2: Database | C2: Scopus | D2: 46282 | F2: Intelligent driving foundation model; [智能驾驶大模型] | G2: Hu J.; Huang L.; Zhai W.; Yan R.; Li C.; Zheng W.; He R.; Zha Z.; Xiong H. | H2: 2026 | I2: Journal of Image and Graphics | J2: 10.11834/jig.260085 | K2: https://www.scopus.com/pages/publications/105043177703?origin=resultslist | L2: The intelligent driving foundation model integrates vision, language, and action through multimodal learning, shifting autonomous driving from traditional perception-planning-control architectures toward unified end-to-end systems. It enhances robustness, decision-making, and generalization through unified representation, generative reasoning, and few-shot learning. This review summarizes recent advances in decision planning, environmental perception, visual question answering, and data generation. Large language and multimodal models improve interpretability, semantic understanding, trajectory prediction, and interaction between autonomous vehicles and humans. Visual question answering enables models to explain driving decisions and respond to semantic queries, while retrieval-augmented generation and chain-of-thought techniques further improve reasoning. To address the high cost and limited coverage of driving data, research increasingly focuses on automatic annotation, self-supervised learning, generative data synthesis, and world models. The review also compares international and Chinese developments, highlighting differences in multimodal integration, engineering applications, data systems, and computational optimization. Future research should focus on real-time performance, safety, personalization, trustworthy AI evaluation, open data infrastructure, and human-AI alignment. | M2: Article | N2: English | O2: =IF(F2="","",LOWER(TRIM(F2)&"|"&TRIM(G2)&"|"&H2)) | P2: No
A3: A0002 | B3: Database | C3: Scopus | D3: 46282 | F3: What Drives Success in Physical Planning with Joint-Embedding Predictive World Models? | G3: Terver B.; Yang T.-Y.; Ponce J.; Bardes A.; Cun Y.L. | H3: 2026 | I3: Transactions on Machine Learning Research | J3: - | K3: https://www.scopus.com/pages/publications/105039617137?origin=resultslist | L3: A long-standing challenge in AI is to develop agents capable of solving a wide range of physical tasks and generalizing to new, unseen tasks and environments. A popular recent approach involves training a world model from state-action trajectories and subsequently using it with a planning algorithm to solve new tasks. Planning is commonly performed in the input space, but a recent family of methods has introduced planning algorithms that optimize in the learned representation space of the world model, with the promise that abstracting irrelevant details yields more efficient planning. In this work, we characterize models from this family as JEPA-WMs and investigate the technical choices that make algorithms from this class work. We propose a comprehensive study of several key components with the objective of finding the optimal approach within the family. We conducted experiments using both simulated environments and real-world robotic data, and studied how the model architecture, the training objective, and the planning algorithm affect planning success. We combine our findings to propose a model that outperforms two established baselines, DINO-WM and V-JEPA-2-AC, in both navigation and manipulation tasks. Code, data and checkpoints are available at https://github.com/facebookresearch/jepa-wms. © 2026, Transactions on Machine Learning Research. All rights reserved. | M3: Article | N3: English | O3: =IF(F3="","",LOWER(TRIM(F3)&"|"&TRIM(G3)&"|"&H3)) | P3: No
A4: A0003 | B4: Database | C4: Scopus | D4: 46282 | F4: Structured Dynamics in the Algorithmic Agent | G4: Ruffini G.; Castaldo F.; Vohryzek J. | H4: 2026 | I4: Entropy | J4: 10.3390/e27010090 | K4: https://www.scopus.com/pages/publications/85215784438?origin=resultslist | L4: In the Kolmogorov Theory of Consciousness, algorithmic agents utilize inferred compressive models to track coarse-grained data produced by simplified world models, capturing regularities that structure subjective experience and guide action planning. Here, we study the dynamical aspects of this framework by examining how the requirement of tracking natural data drives the structural and dynamical properties of the agent. We first formalize the notion of a generative model using the language of symmetry from group theory, specifically employing Lie pseudogroups to describe the continuous transformations that characterize invariance in natural data. Then, adopting a generic neural network as a proxy for the agent dynamical system and drawing parallels to Noether’s theorem in physics, we demonstrate that data tracking forces the agent to mirror the symmetry properties of the generative world model. This dual constraint on the agent’s constitutive parameters and dynamical repertoire enforces a hierarchical organization consistent with the manifold hypothesis in the neural network. Our findings bridge perspectives from algorithmic information theory (Kolmogorov complexity, compressive modeling), symmetry (group theory), and dynamics (conservation laws, reduced manifolds), offering insights into the neural correlates of agenthood and structured experience in natural systems, as well as the design of artificial intelligence and computational models of the brain. © 2025 by the authors. | M4: Article | N4: English | O4: =IF(F4="","",LOWER(TRIM(F4)&"|"&TRIM(G4)&"|"&H4)) | P4: No
A5: A0004 | B5: Database | C5: Scopus | D5: 46282 | F5: Hybrid intelligence systems for reliable automation: advancing knowledge work and autonomous operations with scalable AI architectures | G5: Grosvenor A.; Zemlyansky A.; Wahab A.; Bohachov K.; Dogan A.; Deighan D. | H5: 2026 | I5: Frontiers in Robotics and AI | J5: Frontiers in Robotics and AI | K5: https://www.scopus.com/pages/publications/105012031405?origin=resultslist | L5: Introduction: Mission-critical automation demands decision-making that is explainable, adaptive, and scalable—attributes elusive to purely symbolic or data-driven approaches. We introduce a hybrid intelligence (H-I) system that fuses symbolic reasoning with advanced machine learning via a hierarchical architecture, inspired by cognitive frameworks like Global Workspace Theory (Baars, A Cognitive Theory of Consciousness, 1988). Methods: This architecture operates across three levels to achieve autonomous, end-to-end workflows: Navigation: Using Vision Transformers, and graph-based neural networks, the system navigates file systems, databases, and software interfaces with precision. Discrete Actions: Multi-framework automated machine learning (AutoML) trains agents to execute discrete decisions, augmented by Transformers and Joint Embedding Predictive Architectures (JEPA) (Assran et al., 2023, 15619–15629) for complex time-series analysis, such as anomaly detection. Planning: Reinforcement learning, world model-based reinforcement learning, and model predictive control orchestrate adaptive workflows tailored to user requests or live system demands. Results: The system’s capabilities are demonstrated in two mission-critical applications: Space Domain Awareness, Satellite Behavior Detection: A graph-based JEPA paired with multi-agent reinforcement learning enables near real-time anomaly detection across 15,000 on-orbit objects, delivering a precision-recall score of 0.98. Autonomously Driven Simulation Setup: The system autonomously configures Computational Fluid Dynamics (CFD) setups, with an AutoML-driven optimizer enhancing the meshing step—boosting boundary layer capture propagation (BL-CP) from 8% to 98% and cutting geometry failure rates from 88% to 2% on novel aircraft geometries. Scalability is a cornerstone, with the distributed training pipeline achieving linear scaling across 2,000 compute nodes for AI model training, while secure model aggregation incurs less than 4% latency in cross-domain settings. Discussion: By blending symbolic precision with data-driven adaptability, this hybrid intelligence system offers a robust, transferable framework for automating complex knowledge work in domains like space operations and engineering simulations—and adjacent applications such as autonomous energy and industrial facility operations, paving the way for next-generation industrial AI systems. Copyright © 2025 Grosvenor, Zemlyansky, Wahab, Bohachov, Dogan and Deighan. | M5: Article | N5: English | O5: =IF(F5="","",LOWER(TRIM(F5)&"|"&TRIM(G5)&"|"&H5)) | P5: No
A6: A0005 | B6: Database | C6: Scopus | D6: 46282 | F6: World4RL: Diffusion World Models for Policy Refinement with Reinforcement Learning for Robotic Manipulation | G6: Jiang Z.; Liu K.; Qin Y.; Tian S.; Zheng Y.; Zhou M.; Zhang Z.; Yu C.; Li H.; Zhao D. | H6: 2026 | I6: IEEE Robotics and Automation Letters | J6: 10.1109/LRA.2026.3728345 | K6: https://www.scopus.com/pages/publications/105050194365?origin=resultslist | L6: Robotic manipulation policies are commonly initialized through imitation learning, but their performance is limited by the scarcity and narrow coverage of expert data. Reinforcement learning can refine policies to alleviate this limitation, yet real-robot training is costly and unsafe, while training in simulators suffers from the sim-to-real gap. Recent advances in generative models have demonstrated remarkable capabilities in real-world simulation, with diffusion models in particular excelling at generation. This raises the question of how diffusion model-based world models can be combined to enhance pre-trained policies in robotic manipulation. In this work, we propose World4RL, a two-stage system-level framework for robotic manipulation that uses a frozen diffusion visual world model as an imagined environment for reinforcement-learning-based policy refinement. Unlike prior works that primarily employ world models for planning, our framework enables direct end-to-end policy optimization. World4RL is designed around two principles: pre-training a diffusion world model that captures diverse dynamics on multi-task datasets and refining policies entirely within a frozen world model to avoid online real-world interactions. Extensive simulation and real-world experiments demonstrate that World4RL provides high-fidelity environment modeling and enables consistent policy refinement, yielding significantly higher success rates compared to imitation learning and other baselines. © 2016 IEEE. | M6: Article | N6: English | O6: =IF(F6="","",LOWER(TRIM(F6)&"|"&TRIM(G6)&"|"&H6)) | P6: Yes
A7: A0006 | B7: Database | C7: Scopus | D7: 46282 | F7: Generative World Modeling for Risk-Aware Autonomous UAV Navigation in Dynamic Traffic Networks | G7: Momani A.M.; Alsekait D.M.; Al-Khasawneh M.A.; Othman S.H.; Al-Tarawneh I.; Sharma N.; Khoh W.H. | H7: 2026 | I7: Computers, Materials and Continua | J7: 10.32604/cmc.2026.082572 | K7: https://www.scopus.com/pages/publications/105046080515?origin=resultslist | L7: Unmanned Aerial Vehicles (UAVs) are finding more and more applications in logistics, surveillance, and other operations at a large scale. However, autonomous navigation in dynamic traffic situations is not an easy task due to limited energy, moving obstacles, and inter-agent interactions. The proposed paper can be discussed as a Generative World Modeling (GWM) framework of risk-focused UAV navigation in the dynamic traffic network. This paper proposes a GWM framework for risk-aware UAV navigation in dynamic traffic networks. The proposed design incorporates three key elements; a generative world model for predicting future environmental conditions, a diffusion-based trajectory-generation component that generates multiple possible paths, and a risk-aware decision-making component that selects trajectories based on energy use, collision avoidance, and mission criteria. The framework is also extended to the case of a multi-UAV swarm, where a coordinated swarm is facilitated by shared representations in the latent space to alleviate potential conflicts. The experimental analysis of real-world-inspired UAV trajectory data indicates that the proposed GWM framework outperforms the classical, reinforcement-based, and conflict-aware baseline approaches across a range of performance metrics, including mission success rate, delivery time, energy cost, safety, and path efficiency. The findings indicate that with risk-sensitive and generative prediction, autonomous UAV missions should be more robust, effective, and secure in uncertain, complex environments. Copyright © 2026 The Authors. | M7: Article | N7: English | O7: =IF(F7="","",LOWER(TRIM(F7)&"|"&TRIM(G7)&"|"&H7)) | P7: No
A8: A0007 | B8: Database | C8: IEEE Xplore | D8: 46282 | F8: Offline Inverse Constrained Reinforcement Learning for Safe-Critical Decision Making in Healthcare | G8: N. Fang; G. Liu; W. Gong | H8: 2026 | I8: IEEE Transactions on Artificial Intelligence | J8: 10.1109/TAI.2025.3610390 | K8: https://ieeexplore.ieee.org/document/11168453 | L8: One important application of reinforcement learning (RL) is optimizing treatment decisions in healthcare. However, a naïve RL policy can lead to unsafe medical decisions, such as excessive dosages or abrupt treatment changes, often because agents fail to account for common-sense constraints. To mitigate these problems, constrained reinforcement learning (CRL) naturally emerges as a promising approach for safer decision-making by optimizing policies under predefined constraints. To extend CRL to healthcare applications, a fundamental challenge lies in accurately specifying the constraint function for different healthcare scenarios. Recent inverse constrained reinforcement learning (ICRL) is a promising approach that infers constraints from expert demonstrations. However, ICRL algorithms model Markovian decisions and rely on real-time interactive environments. These settings do not align with the practical requirement of a decision-making system in healthcare, where decisions rely on historical treatment recorded in an offline dataset. To tackle these issues, we propose the constraint transformer (CT). Specifically, 1) we utilize a causal attention mechanism to incorporate historical decisions and observations into the constraint modeling, while employing a non-Markovian layer for weighted constraints to capture critical states. 2) A generative world model is used for exploratory data augmentation, enabling offline RL methods to simulate unsafe decision sequences. In multiple medical scenarios, empirical results demonstrate that CT can capture unsafe states and achieve strategies that approximate lower mortality rates, reducing the occurrence probability of unsafe behaviors. | M8: Journal Article | N8: English | O8: =IF(F8="","",LOWER(TRIM(F8)&"|"&TRIM(G8)&"|"&H8)) | P8: No
A9: A0008 | B9: Database | C9: IEEE Xplore | D9: 46282 | F9: World4RL: Diffusion World Models for Policy Refinement With Reinforcement Learning for Robotic Manipulation | G9: Z. Jiang; K. Liu; Y. Qin; S. Tian; Y. Zheng; M. Zhou; Z. Zhang; C. Yu; H. Li; D. Zhao | H9: 2026 | I9: IEEE Robotics and Automation Letters | J9: 10.1109/LRA.2026.3728345 | K9: https://ieeexplore.ieee.org/document/11668663 | L9: Robotic manipulation policies are commonly initialized through imitation learning, but their performance is limited by the scarcity and narrow coverage of expert data. Reinforcement learning can refine policies to alleviate this limitation, yet real-robot training is costly and unsafe, while training in simulators suffers from the sim-to-real gap. Recent advances in generative models have demonstrated remarkable capabilities in real-world simulation, with diffusion models in particular excelling at generation. This raises the question of how diffusion model-based world models can be combined to enhance pre-trained policies in robotic manipulation. In this work, we propose World4RL, a two-stage system-level framework for robotic manipulation that uses a frozen diffusion visual world model as an imagined environment for reinforcement-learning-based policy refinement. Unlike prior works that primarily employ world models for planning, our framework enables direct end-to-end policy optimization. World4RL is designed around two principles: pre-training a diffusion world model that captures diverse dynamics on multi-task datasets and refining policies entirely within a frozen world model to avoid online real-world interactions. Extensive simulation and real-world experiments demonstrate that World4RL provides high-fidelity environment modeling and enables consistent policy refinement, yielding significantly higher success rates compared to imitation learning and other baselines. © 2016 IEEE. | M9: Journal Article | N9: English | O9: =IF(F9="","",LOWER(TRIM(F9)&"|"&TRIM(G9)&"|"&H9)) | P9: Yes
A10: A0009 | B10: Database | C10: ScienceDirect | D10: 46283 | E10: ("world model" OR "world models") AND ("JEPA" OR "generative" OR "diffusion") AND ("video prediction" OR "planning" OR "probing") | F10: Large language model-based planning agent with generative memory strengthens performance in textualized world | G10: Liu, Junyang; Hao, Wenning; Cheng, Kai; Jin, Dawei | H10: 2025 | I10: Engineering Applications of Artificial Intelligence | J10: 10.1016/j.engappai.2025.110319 | K10: https://www.sciencedirect.com/science/article/pii/S0952197625003197 | L10: This paper constructs a planning agent with generative memory (GM-Agent) based on Large Language Models (LLM) to address the complex planning problems in textualized world. GM-Agent perceives and makes decisions by representing the world as a quintuple, constructing a textualized world model (TWM), and generating memory. Its generative rewards and strategies can optimize the decision-making performance. Baseline results demonstrate that under the LandWar benchmark, compared with prompt-based generative agents and the traditional Reinforcement Learning from Human Feedback (RLHF) framework, GM-Agent can exhibit stronger continuous planning capabilities. The degree to which GM-Agent follows instructions has increased by 137.25%, and the degree to which its decisions are aligned with human experience has increased by 51.69%. The execution ability of mainline tasks and the convergence performance of the model demonstrate state-of-the-arts (SOTA). In comparisons with various benchmark artificial intelligences (AIs), GM-Agent performs excellently, especially showing obvious advantages in adversarial tasks, with a maximum 96.08% improvement in the performance of mainline tasks. Orthogonal experiments prove the effectiveness of the proposed reward scoring and advantage function. We have demonstrated the framework portability and application scenario generalization capabilities of GM-Agent in different LLM frameworks and benchmarks in different fields. It shows excellent performance in the complex field of embodied intelligence planning. However, there is still a certain gap compared with advanced technologies in scientific common sense and logical reasoning tasks. We have demonstrated the application potential of GM-Agent in multiple application scenarios, and found its deficiencies in terms of stability, observation subjectivity, feedback ability, and flexibility. | M10: Research article | N10: English | O10: liu2025large | P10: No | Q10: Hasil pencarian primer ScienceDirect. Berfokus pada textualized world model (TWM) dan LLM. Catatan awal untuk tahap screening: berpotensi dieksklusi pada kriteria EC4 karena domain berupa teks, bukan sekuens visual/video.
A11: A0010 | B11: Database | C11: ScienceDirect | D11: 46283 | E11: ("world model" OR "world models") AND ("JEPA" OR "generative" OR "diffusion") AND ("video prediction" OR "planning" OR "probing") | F11: Automation of PCB autorouting via world-model reinforcement learning and freerouting integration | G11: Liao, Yin-Chi; Pan, Sheng-Xin; Chiang, Po-Jui | H11: 2026 | I11: Expert Systems with Applications | J11: 10.1016/j.eswa.2026.131424 | K11: https://www.sciencedirect.com/science/article/pii/S0957417426003374 | L11: We present DreamerV3+FR, a model-based reinforcement learning framework that automates Printed Circuit Board (PCB) routing by integrating a latent world model with the FreeRouting environment. Unlike traditional model-free approaches, our system utilizes latent imagination to simulate multi-step trajectories and optimize net ordering before physical execution, significantly reducing exploration costs and ensuring geometric validity. Empirical evaluation establishes a new state-of-the-art: the framework achieves a 96% completion rate and reduces training time by 21% compared to Deep Q-Networks (DQN). Furthermore, we identify a scalability bottleneck in competing paradigms: while model-free methods like Proximal Policy Optimization (PPO)) fail to adapt to the sparse-reward setting, Generative AI (VAE+GAN) and Large Language Model (LLM) agents falter due to probabilistic design rule violations and spatial hallucinations respectively. In contrast, our world-model approach successfully generalizes to unseen 6-layer PCBs, maintaining 97.6% Signal/Power Integrity (SI/PI) efficiency where others collapse. With a ~50× reduction in design iteration time compared to manual workflows and the lowest recorded rework rate, the proposed framework offers a robust, scalable foundation for end-to-end electronic design automation. [https://github.com/yinqimakeitfun/dreamer-Autorouting/tree/main](https://github.com/yinqimakeitfun/dreamer-Autorouting/tree/main) | M11: Research article | N11: English | O11: liao2026automation | P11: No
A12: A0011 | B12: Database | C12: OpenAlex | D12: 46287 | E12: Multiple queries (Q1-Q10) | F12: Understanding World or Predicting Future? A Comprehensive Survey of World Models | G12: Jingtao Ding; Yunke Zhang; Yu Shang; Y. Zhang; Zefang Zong; Jie Feng; Yuan Yuan; Hongyuan Su; Nian Li; Nicholas Sukiennik; Fengli Xu; Yong Li | H12: 2025 | I12: ACM Computing Surveys | J12: 10.1145/3746449 | K12: https://doi.org/10.1145/3746449 | L12: The concept of world models has garnered significant attention due to advancements in multimodal large language models such as GPT-4 and video generation models such as Sora, which are central to the pursuit of artificial general intelligence. This survey offers a comprehensive review of the literature on world models. Generally, world models are regarded as tools for either understanding the present state of the world or predicting its future dynamics. This review presents a systematic categorization of world models, emphasizing two primary functions: (1) constructing internal representations to understand the mechanisms of the world, and (2) predicting future states to simulate and guide decision-making. Initially, we examine the current progress in these two categories. We then explore the application of world models in key domains, including autonomous driving, robotics, and social simulacra, with a focus on how each domain utilizes these aspects. Finally, we outline key challenges and provide insights into potential future research directions. We summarize the representative articles along with their code repositories in https://github.com/tsinghua-fib-lab/World-Model . | M12: article | N12: en | O12: =IF(F12="","",LOWER(TRIM(F12)&"|"&TRIM(G12)&"|"&H12)) | P12: No | Q12: Citations: 57
A13: A0012 | B13: Database | C13: OpenAlex | D13: 46287 | E13: Multiple queries (Q1-Q10) | F13: Prospective Role of Foundation Models in Advancing Autonomous Vehicles | G13: Jianhua Wu; Bingzhao Gao; Jincheng Gao; Jianhao Yu; Hongqing Chu; Qiankun Yu; Xun Gong; Yi Chang; H. Eric Tseng; Hong Chen; Jie Chen | H13: 2024 | I13: Research | J13: 10.34133/research.0399 | K13: https://doi.org/10.34133/research.0399 | L13: With the development of artificial intelligence and breakthroughs in deep learning, large-scale foundation models (FMs), such as generative pre-trained transformer (GPT), Sora, etc., have achieved remarkable results in many fields including natural language processing and computer vision. The application of FMs in autonomous driving holds considerable promise. For example, they can contribute to enhancing scene understanding and reasoning. By pre-training on rich linguistic and visual data, FMs can understand and interpret various elements in a driving scene, and provide cognitive reasoning to give linguistic and action instructions for driving decisions and planning. Furthermore, FMs can augment data based on the understanding of driving scenarios to provide feasible scenes of those rare occurrences in the long tail distribution that are unlikely to be encountered during routine driving and data collection. The enhancement can subsequently lead to improvement in the accuracy and reliability of autonomous driving systems. Another testament to the potential of FMs' applications lies in world models, exemplified by the DREAMER series, which showcases the ability to comprehend physical laws and dynamics. Learning from massive data under the paradigm of self-supervised learning, world models can generate unseen yet plausible driving environments, facilitating the enhancement in the prediction of road users' behaviors and the off-line training of driving strategies. In this paper, we synthesize the applications and future trends of FMs in autonomous driving. By utilizing the powerful capabilities of FMs, we strive to tackle the potential issues stemming from the long-tail distribution in autonomous driving, consequently advancing overall safety in this domain. | M13: article | N13: en | O13: =IF(F13="","",LOWER(TRIM(F13)&"|"&TRIM(G13)&"|"&H13)) | P13: No | Q13: Citations: 20
A14: A0013 | B14: Database | C14: OpenAlex | D14: 46287 | E14: Multiple queries (Q1-Q10) | F14: When Remote Sensing Meets Foundation Model: A Survey and Beyond | G14: Chunlei Huo; Keming Chen; Shuaihao Zhang; Zeyu Wang; Heyu Yan; Jing Shen; Yu Hong; G. R. Qi; Hongmei Fang; Zihan Wang | H14: 2025 | I14: Remote Sensing | J14: 10.3390/rs17020179 | K14: https://doi.org/10.3390/rs17020179 | L14: Most deep-learning-based vision tasks rely heavily on crowd-labeled data, and a deep neural network (DNN) is usually impacted by the laborious and time-consuming labeling paradigm. Recently, foundation models (FMs) have been presented to learn richer features from multi-modal data. Moreover, a single foundation model enables zero-shot predictions on various vision tasks. The above advantages make foundation models better suited for remote sensing images, where image annotations are more sparse. However, the inherent differences between natural images and remote sensing images hinder the applications of the foundation model. In this context, this paper provides a comprehensive review of common foundation models and domain-specific foundation models for remote sensing, and it summarizes the latest advances in vision foundation models, textually prompted foundation models, visually prompted foundation models, and heterogeneous foundation models. Despite the great potential of foundation models for vision tasks, open challenges concerning data, model, and task impact the performance of remote sensing images and make foundation models far from practical applications. To address open challenges and reduce the performance gap between natural images and remote sensing images, this paper discusses open challenges and suggests potential directions for future advancements. | M14: article | N14: en | O14: =IF(F14="","",LOWER(TRIM(F14)&"|"&TRIM(G14)&"|"&H14)) | P14: No | Q14: Citations: 47
A15: A0014 | B15: Database | C15: OpenAlex | D15: 46287 | E15: Multiple queries (Q1-Q10) | F15: A Survey on Vision--Language--Action Models for Embodied AI | G15: Yueen Ma; Zixing Song; Yuzheng Zhuang; Jianye Hao; Irwin King | H15: 2026 | I15: IEEE Transactions on Neural Networks and Learning Systems | J15: 10.1109/tnnls.2025.3650584 | K15: https://doi.org/10.1109/tnnls.2025.3650584 | L15: Embodied AI is widely recognized as a cornerstone of artificial general intelligence (AGI) because it involves controlling embodied agents to perform tasks in the physical world. Building on the success of large language models (LLMs) and vision-language models (VLMs), a new category of multimodal models-referred to as vision-language-action (VLA) models-has emerged to address language-conditioned robotic tasks in embodied AI by leveraging their distinct ability to generate actions. The recent proliferation of VLAs necessitates a comprehensive survey to capture the rapidly evolving landscape. To this end, we present the first survey on VLAs for embodied AI. This work provides a detailed taxonomy of VLAs, organized into three major lines of research. The first line focuses on individual components of VLAs. The second line is dedicated to developing VLA-based control policies adept at predicting low-level actions. The third line comprises high-level task planners capable of decomposing long-horizon tasks into a sequence of subtasks, thereby guiding VLAs to follow more general user instructions. Furthermore, we provide an extensive summary of relevant resources, including datasets, simulators, and benchmarks. Finally, we discuss the challenges facing VLAs and outline promising future directions in embodied AI. A curated repository associated with this survey is available at: https://github.com/yueen-ma/Awesome-VLA. | M15: article | N15: en | O15: =IF(F15="","",LOWER(TRIM(F15)&"|"&TRIM(G15)&"|"&H15)) | P15: No | Q15: Citations: 29
A16: A0015 | B16: Database | C16: OpenAlex | D16: 46287 | E16: Multiple queries (Q1-Q10) | F16: Towards Generalist Robot Learning from Internet Video: A Survey | G16: Robert McCarthy; Daniel C. H. Tan; Dominik Schmidt; Fernando Acero; Nathan Herr; Yilun Du; Thomas George Thuruthel; Zhibin Li | H16: 2025 | I16: Journal of Artificial Intelligence Research | J16: 10.1613/jair.1.17400 | K16: https://doi.org/10.1613/jair.1.17400 | L16: Scaling deep learning to massive and diverse internet data has driven remarkable breakthroughs in domains such as video generation and natural language processing. Robot learning, however, has thus far failed to replicate this success and remains constrained by a scarcity of available data. Learning from Videos (LfV) methods aim to address this data bottleneck by augmenting traditional robot data with large-scale internet video. This video data provides foundational information regarding physical dynamics, behaviours, and tasks, and can be highly informative for general-purpose robots. This survey systematically examines the emerging field of LfV. We first outline essential concepts, including detailing fundamental LfV challenges such as distribution shift and missing action labels in video data. Next, we comprehensively review current methods for extracting knowledge from large-scale internet video, overcoming LfV challenges, and improving robot learning through video-informed training. The survey concludes with a critical discussion of future opportunities. Here, we emphasize the need for scalable foundation model approaches that can leverage the full range of available internet video and enhance the learning of robot policies and dynamics models. Overall, the survey aims to inform and catalyse future LfV research, driving progress towards general-purpose robots. | M16: article | N16: en | O16: =IF(F16="","",LOWER(TRIM(F16)&"|"&TRIM(G16)&"|"&H16)) | P16: No | Q16: Citations: 8
A17: A0016 | B17: Database | C17: OpenAlex | D17: 46287 | E17: Multiple queries (Q1-Q10) | F17: Research on World Models for Connected Automated Driving: Advances, Challenges, and Outlook | G17: Nuo Chen; Xiang Liu | H17: 2025 | I17: Applied Sciences | J17: 10.3390/app15168986 | K17: https://doi.org/10.3390/app15168986 | L17: Connected Autonomous Vehicles (CAVs) technology holds immense potential for enhancing traffic safety and efficiency; however, its inherent complexity presents significant challenges for conventional autonomous driving. World Models (WMs), an advanced deep learning paradigm, offer an innovative approach to address these CAV challenges by learning environmental dynamics and precisely predicting future states. This survey systematically reviews the advancements of WMs in connected automated driving, delving into the key methodologies and technological breakthroughs across six core application domains: cooperative perception, prediction, decision-making, control, human–machine collaboration, and scene generation. Furthermore, this paper critically analyzes the current limitations of WMs in CAV scenarios, particularly concerning multi-source heterogeneous data fusion, physical law mapping, long-term temporal memory, and cross-scenario generalization capabilities. Building upon this analysis, we prospectively outline future research directions aimed at fostering the development of more robust, efficient, and interpretable WMs. Ultimately, this work aims to provide a crucial reference for constructing safe, efficient, and sustainable connected automated driving systems. | M17: article | N17: en | O17: =IF(F17="","",LOWER(TRIM(F17)&"|"&TRIM(G17)&"|"&H17)) | P17: No | Q17: Citations: 3
A18: A0017 | B18: Database | C18: OpenAlex | D18: 46287 | E18: Multiple queries (Q1-Q10) | F18: When Does Sora Show: The Beginning of TAO to Imaginative Intelligence and Scenarios Engineering | G18: Fei–Yue Wang; Qinghai Miao; Lingxi Li; Qinghua Ni; Xuan Li; Juanjuan Li; Lili Fan; Yonglin Tian; Qing‐Long Han | H18: 2024 | I18: IEEE/CAA Journal of Automatica Sinica | J18: 10.1109/jas.2024.124383 | K18: https://doi.org/10.1109/jas.2024.124383 | L18: During our discussion at workshops for writing “What Does ChatGPT Say: The DAO from Algorithmic Intelligence to Linguistic Intelligence” [1], we had expected the next milestone for Artificial Intelligence (AI) would be in the direction of Imaginative Intelligence (II), i.e., something similar to automatic words-to-videos generation or intelligent digital movies/theater technology that could be used for conducting new “Artificiofactual Experiments” [2] to replace conventional “Counterfactual Experiments” in scientific research and technical development for both natural and social studies [2]–[6]. Now we have OpenAI's Sora, so soon, but this is not the final, actually far away, and it is just the beginning. | M18: article | N18: en | O18: =IF(F18="","",LOWER(TRIM(F18)&"|"&TRIM(G18)&"|"&H18)) | P18: No | Q18: Citations: 63
A19: A0018 | B19: Database | C19: OpenAlex | D19: 46287 | E19: Multiple queries (Q1-Q10) | F19: Latent Prediction-Based Generative Semantic Communication for Video Transmission in Wireless Networks | G19: Maheshi Lokumarambage; Thushan Sivalingam; Feng Dong; Nandana Rajatheva; Anil Fernando | H19: 2026 | I19: IEEE Open Journal of the Communications Society | J19: 10.1109/ojcoms.2026.3684230 | K19: https://doi.org/10.1109/ojcoms.2026.3684230 | L19: The increasing dominance of video traffic in intelligent sensing and control applications introduces a major challenge to the capacity limits of modern wireless networks. Classical information theory defines fixed physical boundaries on channel capacity, beyond which further improvement requires rethinking what information is transmitted. Semantic communication (SemCom) bridges this by only sending the semantics of the intended message. This paper presents a SemCom framework that leverages latent-space procedural video prediction with world-model-guided temporal dynamics. Instead of transmitting pixel data, the transmitter encodes high-level semantic representations of context frames and sends them through the physical channel. A temporal transformer predicts future latent states at the receiver. The framework jointly optimizes perceptual, adversarial, and temporal objectives to preserve both visual quality and trajectory consistency under channel impairments. Experiments conducted on video sequences of the BAIR robot pushing dataset demonstrate that the proposed method achieves lower normalized endpoint and velocity errors compared to learned baseline real-time intermediate flow estimation (RIFE) + better portable graphics (BPG) with reduced bit-rate compared to traditional codecs. The results indicate that incorporating temporal dynamics as semantics into the communication process enables efficient and anticipatory video transmission suitable for applications such as tele-robotic, underwater, and autonomous systems. | M19: article | N19: en | O19: =IF(F19="","",LOWER(TRIM(F19)&"|"&TRIM(G19)&"|"&H19)) | P19: No | Q19: Citations: 1
A20: A0019 | B20: Database | C20: OpenAlex | D20: 46287 | E20: Multiple queries (Q1-Q10) | F20: Generative emergent communication: large language model is a collective world model | G20: Tadahiro Taniguchi; Ryo Ueda; Tomoaki Nakamura; Masahiro Suzuki; Akira Taniguchi | H20: 2026 | I20: Advanced Robotics | J20: 10.1080/01691864.2026.2661958 | K20: https://doi.org/10.1080/01691864.2026.2661958 | L20: This survey and perspective paper addresses a fundamental puzzle: how Large Language Models (LLMs) acquire extensive world knowledge without direct sensorimotor experience. We introduce the Collective World Model hypothesis, arguing that an LLM does not learn a world model from scratch. Instead, it learns a statistical approximation of a collective world model already implicitly encoded in human language through a society-wide process of embodied, interactive sense-making. To formalize this process, we introduce the generative emergent communication (Generative EmCom) framework, built upon Collective Predictive Coding (CPC). This framework models language emergence as decentralized Bayesian inference, effectively creating an encoder-decoder structure at a societal scale: human society collectively encodes its grounded representations into language, and an LLM decodes these symbols to reconstruct a latent space mirroring the original structure. This perspective offers a principled explanation for how LLMs acquire their capabilities. We formalize the Generative EmCom framework, connecting it to world models and multi-agent reinforcement learning, and apply it to interpret LLMs, explaining phenomena like distributional semantics as a natural consequence of representation reconstruction. This work provides a unified theory that bridges individual cognitive development, collective language evolution, and the foundations of large-scale AI. | M20: article | N20: en | O20: =IF(F20="","",LOWER(TRIM(F20)&"|"&TRIM(G20)&"|"&H20)) | P20: No | Q20: Citations: 2
